Workbook

Sheet DashboardData
A1: Agent Name | B1: Weekly Target | C1: Weekly Done | D1: Weekly Need | E1: Monitor Target | F1: Monitor On | G1: Monitor Need | H1: Commission Target | I1: Commission On | J1: Commission Need
A2: Sandy M | B2: =Sheet1!B15 -> 16170 | C2: =Sheet1!B16 -> 9390 | D2: =B2-C2 -> 6780 | E2: =Sheet1!B36 -> 60000 | F2: =Sheet1!B35 -> 15620 | G2: =E2-F2 -> 44380
A3: Abigail W | B3: =Sheet1!C15 -> 12000 | C3: =Sheet1!C16 -> 11310 | D3: =B3-C3 -> 690 | E3: =Sheet1!C36 -> 60000 | F3: =Sheet1!C35 -> 15770 | G3: =E3-F3 -> 44230
A4: Marizaan R | B4: =Sheet1!D15 -> 15000 | C4: =Sheet1!D16 -> 9065 | D4: =B4-C4 -> 5935 | E4: =Sheet1!D36 -> 45000 | F4: =Sheet1!D35 -> 11075 | G4: =E4-F4 -> 33925
A5: Ian S | B5: =Sheet1!E15 -> 12000 | C5: =Sheet1!E16 -> 6535 | D5: =B5-C5 -> 5465 | E5: =Sheet1!E36 -> 45000 | F5: =Sheet1!E35 -> 13275 | G5: =E5-F5 -> 31725
A6: Ethan C | B6: =Sheet1!F15 -> 9000 | C6: =Sheet1!F16 -> 0 | D6: =B6-C6 -> 9000 | E6: =Sheet1!F36 -> 20000 | F6: =Sheet1!F35 -> 1200 | G6: =E6-F6 -> 18800
A7: Jan B | B7: =Sheet1!G15 -> 10000 | C7: =Sheet1!G16 -> 2950 | D7: =B7-C7 -> 7050 | E7: =Sheet1!G36 -> 20000 | F7: =Sheet1!G35 -> 4150 | G7: =E7-F7 -> 15850
A8: Zico J | B8: =Sheet1!H15 -> 10000 | C8: =Sheet1!H16 -> 7160 | D8: =B8-C8 -> 2840 | E8: =Sheet1!H36 -> 20000 | F8: =Sheet1!H35 -> 24495 | G8: =E8-F8 -> -4495
A9: Juandre J | B9: =Sheet1!I15 -> 8000 | C9: =Sheet1!I16 -> 0 | D9: =B9-C9 -> 8000 | E9: =Sheet1!I36 -> 12500 | F9: =Sheet1!I35 -> 5870 | G9: =E9-F9 -> 6630
A10: Chane W | B10: =Sheet1!J15 -> 8500 | C10: =Sheet1!J16 -> 10690 | D10: =B10-C10 -> -2190 | E10: =Sheet1!J36 -> 12500 | F10: =Sheet1!J35 -> 7610 | G10: =E10-F10 -> 4890
A11: Dian S | B11: =Sheet1!K15 -> 6000 | C11: =Sheet1!K16 -> 3240 | D11: =B11-C11 -> 2760 | E11: =Sheet1!K36 -> 12500 | F11: =Sheet1!K35 -> 6260 | G11: =E11-F11 -> 6240
A12: Diaan E | B12: =Sheet1!L15 -> 7000 | C12: =Sheet1!L16 -> 2910 | D12: =B12-C12 -> 4090 | E12: =Sheet1!L36 -> 12500 | F12: =Sheet1!L35 -> 4110 | G12: =E12-F12 -> 8390
A13: Ryan G | B13: =Sheet1!M15 -> 8000 | C13: =Sheet1!M16 -> 0 | D13: =B13-C13 -> 8000 | E13: =Sheet1!M36 -> 5000 | F13: =Sheet1!M35 -> 1200 | G13: =E13-F13 -> 3800
A14: Elmarie K | B14: =Sheet1!N15 -> 8000 | C14: =Sheet1!N16 -> 1200 | D14: =B14-C14 -> 6800 | E14: =Sheet1!N36 -> 5000 | F14: =Sheet1!N35 -> 5220 | G14: =E14-F14 -> -220
A15: Tasneem M | B15: =Sheet1!O15 -> 2500 | C15: =Sheet1!O16 -> 390 | D15: =B15-C15 -> 2110 | E15: =Sheet1!O36 -> 5000 | F15: =Sheet1!O35 -> 390 | G15: =E15-F15 -> 4610
A16: Matthew K | B16: =Sheet1!P15 -> 2500 | C16: =Sheet1!P16 -> 0 | D16: =B16-C16 -> 2500 | E16: =Sheet1!P36 -> 5000 | F16: =Sheet1!P35 -> 0 | G16: =E16-F16 -> 5000

Sheet Sheet1
B2: GEOGRE AGENTS | Q2: TOTAL FOR THE DAY | R2: NEED TO BREAK RECORD DAY
B3: Sandy Mare | C3: Abigail Wehmeyer | D3: Marizaan Read | E3: Ian Stewart | F3: Ethan Campher | G3: Jan Britz | H3: Zico Janse van Rensburg | I3: Juandre Jonck | J3: Chane Wolmarans | K3: Dian Smit | L3: Diaan Engelbrecht | M3: Ryan Grobler | N3: Elmarie Kruger | O3: Tasneem Mohamed | P3: Matthew Knight
A4: 46083 | B4: 0 | C4: 1710 | D4: 1200 | E4: 0 | F4: 1200 | G4: 1200 | H4: 1955 | I4: 0 | J4: 2040 | K4: 0 | L4: 0 | M4: 1200 | Q4: =SUM(B4:M4) -> 10505 | R4: =$C$42-Q4 -> 28140
A5: 46084 | B5: 2010 | C5: 0 | D5: 2010 | E5: 2010 | F5: 0 | G5: 0 | H5: 9010 | I5: 0 | J5: 0 | K5: 0 | L5: 0 | M5: 0 | Q5: =SUM(B5:M5) -> 15040 | R5: =$C$42-Q5 -> 23605
A6: 46085 | B6: 0 | C6: 360 | D6: 0 | E6: 1710 | F6: 1200 | G6: 0 | H6: 0 | I6: 0 | J6: 7820 | K6: 0 | L6: 0 | M6: 0 | N6: 4020 | Q6: =SUM(B6:N6) -> 15110 | R6: =$C$42-Q6 -> 23535
A7: 46086 | B7: 3020 | C7: 680 | D7: 0 | E7: 0 | F7: 0 | G7: 0 | H7: 2400 | I7: 0 | J7: 0 | K7: 0 | L7: 0 | M7: 0 | N7: 0 | Q7: =SUM(B7:M7) -> 6100 | R7: =$C$42-Q7 -> 32545
A8: 46087 | B8: 1200 | C8: 1710 | D8: 0 | E8: 3020 | F8: 0 | G8: 1200 | H8: 3970 | I8: 5870 | J8: 0 | K8: 3020 | L8: 1200 | M8: 0 | N8: 0 | Q8: =SUM(B8:P8) -> 21190 | R8: =$C$42-Q8 -> 17455
A9: WEEK 1 | B9: =B4+B5+B6+B7+B8 -> 6230 | C9: =C4+C5+C6+C7+C8 -> 4460 | D9: =D4+D5+D6+D7+D8 -> 3210 | E9: =E4+E5+E6+E7+E8 -> 6740 | F9: =F4+F5+F6+F7+F8 -> 2400 | G9: =G4+G5+G6+G7+G8 -> 2400 | H9: =H4+H5+H6+H7+H8 -> 17335 | I9: =I4+I5+I6+I7+I8 -> 5870 | ... P9: =P4+P5+P6+P7+P8 -> 0
A10: 46090 | B10: 0 | C10: 3750 | D10: 3970 | E10: 0 | F10: 0 | G10: 0 | H10: 0 | I10: 0 | J10: 3300 | K10: 1200 | L10: 1200 | M10: 0 | N10: 0 | Q10: =SUM(B10:P10) -> 13420 | R10: =$C$42-Q10 -> 25225
A11: 46091 | B11: 1710 | C11: 3930 | D11: 595 | E11: 0 | F11: 0 | G11: 1750 | H11: 2460 | I11: 0 | J11: 4730 | K11: 2040 | L11: 1710 | M11: 0 | N11: 0 | Q11: =SUM(B11:P11) -> 18925 | R11: =$C$42-Q11 -> 19720
A12: 46092 | B12: 2040 | C12: 2670 | D12: 1200 | E12: 2455 | F12: 0 | G12: 0 | H12: 1200 | I12: 0 | J12: 0 | K12: 0 | L12: 0 | M12: 0 | N12: 1200 | Q12: =SUM(B12:P12) -> 10765 | R12: =$C$42-Q12 -> 27880
A13: 46093 | B13: =1710+3930 -> 5640 | C13: 960 | D13: 3300 | E13: 4080 | F13: 0 | G13: 1200 | H13: 3500 | I13: 0 | J13: 1200 | K13: 0 | L13: 0 | M13: 0 | N13: 0 | Q13: =SUM(B13:M13) -> 19880 | R13: =$C$42-Q13 -> 18765
A14: 46094 | J14: 1460 | O14: 390 | Q14: =SUM(B14:M14) -> 1460 | R14: =$C$42-Q14 -> 37185
A15: Week Target | B15: =16170 -> 16170 | C15: =12000 -> 12000 | D15: =15000 -> 15000 | E15: =12000 -> 12000 | F15: =9000 -> 9000 | G15: =10000 -> 10000 | H15: =10000 -> 10000 | I15: =8000 -> 8000 | J15: =8500 -> 8500 | K15: =6000 -> 6000 | L15: =7000 -> 7000 | M15: =8000 -> 8000 | N15: =8000 -> 8000 | O15: 2500 | P15: 2500 | Q15: =SUM(B15:P15) -> 134670 | R15: =$C$42-S20 -> 38645
A16: WEEK 2 | B16: =B10+B11+B12+B13+B14 -> 9390 | C16: =C10+C11+C12+C13+C14 -> 11310 | D16: =D10+D11+D12+D13+D14 -> 9065 | E16: =E10+E11+E12+E13+E14 -> 6535 | F16: =F10+F11+F12+F13+F14 -> 0 | G16: =G10+G11+G12+G13+G14 -> 2950 | H16: =H10+H11+H12+H13+H14 -> 7160 | I16: =I10+I11+I12+I13+I14 -> 0 | ... P16: =P10+P11+P12+P13+P14 -> 0
A17: 46097 | Q17: =SUM(B17:M17) -> 0 | R17: =$C$42-Q17 -> 38645
A18: 46098 | Q18: =SUM(B18:M18) -> 0 | R18: =$C$42-Q18 -> 38645
A19: 46099 | Q19: =SUM(B19:M19) -> 0 | R19: =$C$42-Q19 -> 38645
A20: 46100 | Q20: =SUM(B20:M20) -> 0 | R20: =$C$42-Q20 -> 38645
A21: 46101 | Q21: =SUM(B21:M21) -> 0 | R21: =$C$42-Q21 -> 38645
A22: Week Target
A23: WEEK 3 | B23: =B17+B18+B19+B20+B21 -> 0 | C23: =C17+C18+C19+C20+C21 -> 0 | D23: =D17+D18+D19+D20+D21 -> 0 | E23: =E17+E18+E19+E20+E21 -> 0 | F23: =V19+F18+F19+F20+F21 -> 0 | G23: =G17+G18+G19+G20+G21 -> 0 | H23: =H17+H18+H19+H20+H21 -> 0 | I23: =I17+I18+I19+I20+I21 -> 0 | J23: =J17+J18+J19+J20+J21 -> 0 | K23: =K17+K18+K19+K20+K21 -> 0 | L23: =L17+L18+L19+L20+L21 -> 0 | M23: =M17+M18+M19+M20+M21 -> 0 | N23: =N17+N18+N19+N20+N21 -> 0 | ... P23: =P17+P18+P19+P20+P21 -> 0
A24: 46104 | Q24: =SUM(B24:M24) -> 0 | R24: =$C$42-Q24 -> 38645
A25: 46105 | Q25: =SUM(B25:M25) -> 0 | R25: =$C$42-Q25 -> 38645
A26: 46106 | Q26: =SUM(B26:M26) -> 0 | R26: =$C$42-Q26 -> 38645
A27: 46107 | Q27: =SUM(B27:M27) -> 0 | R27: =$C$42-Q27 -> 38645
A28: 46108 | Q28: =SUM(B28:M28) -> 0 | R28: =$C$42-Q28 -> 38645
A29: Week Target
A30: WEEK 4 | B30: =B24+B25+B26+B27+B28 -> 0 | C30: =C24+C25+C26+C27+C28 -> 0 | D30: =D24+D25+D26+D27+D28 -> 0 | E30: =E24+E25+E26+E27+E28 -> 0 | F30: =F24+F25+F26+F27+F28 -> 0 | G30: =G24+G25+G26+G27+G28 -> 0 | H30: =H24+H25+H26+H27+H28 -> 0 | I30: =I24+I25+I26+I27+I28 -> 0 | ... P30: =P24+P25+P26+P27+P28 -> 0
A31: 46111 | Q31: =SUM(B31:M31) -> 0 | R31: =$C$42-Q31 -> 38645
A32: 46112 | Q32: =SUM(B32:M32) -> 0 | R32: =$C$42-Q32 -> 38645
A33: Week Target
A34: WEEK 5 | B34: =B31+B32 -> 0 | C34: =C31+C32 -> 0 | D34: =D31+D32 -> 0 | E34: =E31+E32 -> 0 | F34: =F31+F32 -> 0 | G34: =G31+G32 -> 0 | H34: =H31+H32 -> 0 | I34: =I31+I32 -> 0 | ... L34: =L31+L32 -> 0 | M34: =M27+M28+M30+M31+M32 -> 0 | N34: =N27+N28+N30+N31+N32 -> 0 | O34: =O27+O28+O30+O31+O32 -> 0 | P34: =P27+P28+P30+P31+P32 -> 0
A35: TOTAL | B35: =B9+B16+B23+B30+B34 -> 15620 | C35: =C9+C16+C23+C30+C34 -> 15770 | D35: =D9+D16+D23+D30+D34-1200 -> 11075 | E35: =E9+E16+E23+E30+E34 -> 13275 | F35: =F9+F16+F23+F30+F34-1200 -> 1200 | G35: =G9+G16+G23+G30+G34-1200 -> 4150 | H35: =H9+H16+H23+H30+H34 -> 24495 | I35: =I9+I16+I23+I30+I34 -> 5870 | J35: =J9+J16+J23+J30+J34-12940 -> 7610 | K35: =K9+K16+K23+K30+K34 -> 6260 | L35: =L9+L16+L23+L30+L34 -> 4110 | M35: =M9+M16+M23+M30+M34 -> 1200 | N35: =N9+N16+N23+N30+N34 -> 5220 | O35: =O9+O16+O23+O30+O34 -> 390 | P35: =P9+P16+P23+P30+P34 -> 0
A36: TARGET | B36: 60000 | C36: 60000 | D36: 45000 | E36: 45000 | F36: 20000 | G36: 20000 | H36: 20000 | I36: 12500 | J36: 12500 | K36: 12500 | L36: 12500 | M36: 5000 | N36: 5000 | O36: 5000 | P36: 5000
A37: NEED | B37: =B36-B35 -> 44380 | C37: =C36-C35 -> 44230 | D37: =D36-D35 -> 33925 | E37: =E36-E35 -> 31725 | F37: =F36-F35 -> 18800 | G37: =G36-G35 -> 15850 | H37: =H36-H35 -> -4495 | I37: =I36-I35 -> 6630 | ... P37: =P36-P35 -> 5000
A38: COMMISSION | B38: =B9+B16+B23+B30+B34+3420 -> 19040 | C38: =C9+C16+C23+C24+C25+C26+8040 -> 23810 | D38: =D9+D16+D23+D24+D25+D26+1830 -> 14105 | E38: =E9+E16+E23+E24+E25+E26+1710 -> 14985 | F38: =F9+F16+F23+F24+F25+F26+1200 -> 3600 | G38: =G9+G16+G23+G24+G25+G26-1200 -> 4150 | H38: =H9+H16+H23+H24+H25+H26+1560 -> 26055 | I38: =I9+I16+I23+I24+I25+I26+0 -> 5870 | J38: =J9+J16+J23+J24+J25+J26+1830 -> 22380 | K38: =K9+K16+K23+K24+K25+K26+2460 -> 8720 | L38: =L9+L16+L23+L24+L25+L26+1560 -> 5670 | M38: =M9+M16+M23+M24+M25+M26 -> 1200 | N38: =N9+N16+N23+N24+N25+N26 -> 5220 | O38: =O9+O16+O23+O24+O25+O26 -> 390 | P38: =P9+P16+P23+P24+P25+P26 -> 0
M40: NEED 1 SALE | O40: NEED 2 SALES | P40: NEED 1SALES
B41: RECORDS | E41: Spanne | F41: Currently On | G41: Required | H41: Still Need
B42: DAY | C42: 38645 | E42: ROOKIES | F42: =SUM(F35:P35) -> 60505 | G42: =SUM(F36:P36) -> 130000 | H42: =G42-F42 -> 69495
...
